Workbook

Sheet PMP Path
B32: If an employee successfully passes their POA/PIP they should remain on a probation period durint the next 2 to 4 weekd to ensure sustained improvement.

Sheet POA- 4 weeks
B2: Plan De Acción
B4: Investigador | C4: Rodrigo Herrera | I4: Inicio | J4: 15 de Febrero de 2026
B6: Gerente directo | C6: Javier Molina | I6: Final | J6: 14 de Marzo de 2026
B8: Áreas de mejora
B9: Investigaciones por hora: Cantidad de investigaciones realizadas de manera diaria/ semanal de acuerdo a los requerimientos especificos de la compañia. Cumplimiento de Horario : Uso de tiempo apropiado para efectuar la investigacion de acuerdo a las metricas establecidas para el tipo de investigacion y para el marketplace en que el investigador se encuentra trabajando. NPT: Tiempo no productivo del investigador asignado por su jefe inmediato. Plataformas de trabajo: PARAGON, GeoFence, Paragon reports, manualmente traqueo investigacions resueltas Componetes de Calidad: Defectos seran medidos semanalas
B12: Objetivo y Compromisos
B13: Objectivo: Alcanzar la cantidad semanal y mensual de investigaciones de acuerdo a los objetivos establecidos por la unidad de negocio, este plan de mejora está enfocado a que maximice su productividad y su tiempo efectivamente Compromiso: El investigador se compromete a cumplir con el plan de mejora, sus objetivos y actividades de una buena manera, apertura a la retroalimentación y voluntad para mejorar de acuerdo a la propuesta del gerente
B14: Medidores de Desempeño Plan de Acción Ultimas 4 Semanas | H14: Metas
H15: 1 | I15: 1 | J15: 1 | K15: 1 | L15: L4-L5 revision de resultado
B16: Investigaciones por hora combinado (IPH) | C16: Semana/Week 3 | D16: Semana/Week 4 | E16: Semana/Week 5 | F16: Semana/Week 6 | G16: Semana/Week 7 | H16: Semana/Week 8 | I16: Semana/Week 9 | J16: Semana/Week 10 | K16: Semana/Week 11 | L16: Week 26/27
C17: =_xlfn.IFNA(VLOOKUP(C16,Sheet2!$A:$B,2,0),"") -> 11 enero 2026 - 17 enero 2026 | D17: =_xlfn.IFNA(VLOOKUP(D16,Sheet2!$A:$B,2,0),"") -> 18 enero 2026 - 24 enero 2026 | E17: =_xlfn.IFNA(VLOOKUP(E16,Sheet2!$A:$B,2,0),"") -> 25 enero 2026 - 31 enero 2026 | F17: =_xlfn.IFNA(VLOOKUP(F16,Sheet2!$A:$B,2,0),"") -> 01 febrero 2026 - 07 febrero 2026 | G17: =_xlfn.IFNA(VLOOKUP(G16,Sheet2!$A:$B,2,0),"") -> 08 febrero 2026 - 14 febrero 2026 | H17: =_xlfn.IFNA(VLOOKUP(H16,Sheet2!$A:$B,2,0),"") -> 15 febrero 2026 - 21 febrero 2026 | I17: =_xlfn.IFNA(VLOOKUP(I16,Sheet2!$A:$B,2,0),"") -> 22 febrero 2026 - 28 febrero 2026 | J17: =_xlfn.IFNA(VLOOKUP(J16,Sheet2!$A:$B,2,0),"") -> 01 marzo 2026 - 07 marzo 2026 | K17: =_xlfn.IFNA(VLOOKUP(K16,Sheet2!$A:$B,2,0),"") -> 08 marzo 2026 - 14 marzo 2026
B18: Meta de Investigaciones Combinadas Por Hora (IPH) | C18: 9.1923739 | D18: 8.941326 | E18: 8.9532496 | F18: 8.3 | G18: 7.93 | H18: 9.5860878 | I18: 8.6031332 | J18: 8.4081958 | K18: 8.5095801 | L18: Notas de resumen
B19: Actual de Investigaciones Combinadas por Hora (IPH) | C19: 8.690776 | D19: 8.6948318 | E19: 8.1041632 | F19: 7.74 | G19: 6.7 | H19: 7.924518 | I19: 10.221275 | J19: 10.023079 | K19: 9.0408697
B20: Resultado Semanal(Cumple/No Cumple) | C20: No Cumple | D20: No Cumple | E20: No Cumple | F20: No Cumple | G20: No Cumple | H20: No Cumple | I20: Cumple | J20: Cumple | K20: Cumple
B21: Componentes de Calidad RR | C21: =C17 -> 11 enero 2026 - 17 enero 2026 | D21: =D17 -> 18 enero 2026 - 24 enero 2026 | E21: =E17 -> 25 enero 2026 - 31 enero 2026 | F21: =F17 -> 01 febrero 2026 - 07 febrero 2026 | G21: =G17 -> 08 febrero 2026 - 14 febrero 2026 | H21: =H17 -> 15 febrero 2026 - 21 febrero 2026 | I21: =I17 -> 22 febrero 2026 - 28 febrero 2026 | J21: =J17 -> 01 marzo 2026 - 07 marzo 2026 | K21: =K17 -> 08 marzo 2026 - 14 marzo 2026 | L21: Week 26/27
B22: Meta de Porcentage de Investigaciones Reversadas (RR Target) | C22: 0.02 | D22: 0.02 | E22: 0.02 | L22: Notas de resumen
B23: Porcentage de Investigaciones Reversadas Obtenido (RR Actual) | C23: 0 | D23: 0 | E23: 0
B24: Controllable defects | C24: 1 | D24: 1 | E24: 0
B25: Resultado Semanal(Cumple/No Cumple) | C25: No Cumple | D25: No Cumple | E25: Cumple
B26: Componentes de Calidad MRR | C26: =C17 -> 11 enero 2026 - 17 enero 2026 | D26: =D17 -> 18 enero 2026 - 24 enero 2026 | E26: =E17 -> 25 enero 2026 - 31 enero 2026 | F26: =F17 -> 01 febrero 2026 - 07 febrero 2026 | G26: =G21 -> 08 febrero 2026 - 14 febrero 2026 | H26: =H17 -> 15 febrero 2026 - 21 febrero 2026 | I26: =I17 -> 22 febrero 2026 - 28 febrero 2026 | J26: =J17 -> 01 marzo 2026 - 07 marzo 2026 | K26: =K17 -> 08 marzo 2026 - 14 marzo 2026 | L26: Week 26/27
B27: Meta de Porcentaje de Restauracion no Realizada (MRR Target) | C27: 0.02 | D27: 0.02 | E27: 0.02 | F27: 0.02 | G27: 0.02 | H27: 0.02 | I27: 0.02 | J27: 0.02 | K27: 0.02 | L27: Notas de resumen
B28: Porcentaje de Restauracion No Realizada Obtenido (MRR Actual) | C28: 0 | D28: 0 | E28: 0 | F28: 0 | G28: 0 | H28: 0 | I28: 0 | J28: 0 | K28: 0
B29: Controllable defects | C29: 1 | D29: 1 | E29: 0 | F29: 0 | G29: 0 | H29: 0 | I29: 0 | J29: 0 | K29: 0
B30: Resultado Semanal(Cumple/No Cumple) | C30: No Cumple | D30: No Cumple | E30: Cumple | F30: Cumple | G30: Cumple | H30: Cumple | I30: Cumple | J30: Cumple | K30: Cumple
B31: Componentes de Calidad CRAR | C31: =C17 -> 11 enero 2026 - 17 enero 2026 | D31: =D17 -> 18 enero 2026 - 24 enero 2026 | E31: =E17 -> 25 enero 2026 - 31 enero 2026 | F31: =F17 -> 01 febrero 2026 - 07 febrero 2026 | G31: =G17 -> 08 febrero 2026 - 14 febrero 2026 | H31: =H17 -> 15 febrero 2026 - 21 febrero 2026 | I31: =I17 -> 22 febrero 2026 - 28 febrero 2026 | J31: =J17 -> 01 marzo 2026 - 07 marzo 2026 | K31: =K17 -> 08 marzo 2026 - 14 marzo 2026 | L31: Week 26/27
B32: Meta de Porcentage de Precision de Respuesta al Cliente (CRAR Target) | C32: 0.95 | D32: 0.95 | E32: 0.95 | F32: 0.95 | G32: 0.95 | H32: 0.95 | I32: 0.95 | J32: 0.95 | K32: 0.95 | L32: Notas de resumen
B33: Porcentage de Precision de Respuesta al Cliente Obtenido (CRAR Actual) | C33: No Data | D33: No Data | E33: 0.8 | F33: 0.56 | G33: 1 | H33: 1 | I33: 0.76 | J33: 0.4 | K33: 1
B34: Resultado Semanal(Cumple/No Cumple) | C34: Cumple | D34: Cumple | E34: No Cumple | F34: No Cumple | G34: Cumple | H34: Cumple | I34: No Cumple | J34: No Cumple | K34: Cumple
B35: Resultados de Investigaciones por Hora (IPH) *resultados seran revisados semanales
B36: Acciones por parte del Investigator | K36: Acciones por parte del Gerente
B37: 1) | C37: El investigador informara de manera inmediata si tuviese algun problema para efectuar investigaciones , siendo problemas con la plataforma Paragon o con cualquier duda que puedan tener acerca del caso. | J37: 1) | K37: El gerente se compromete a dar visibilidad y revisar los resultados obtenidos de forma semanal.
B38: 2) | C38: El investigador se compromete a dejar claras cuales son las posibles faltas de conocimiento que puedan estar afectando su rapidez y calidad en la toma de decisiones | J38: 2) | K38: El gerente se compromete a darle la prioridad necesaria a este plan y sus actividades con el fin de brindar la ayuda requerida para asegurar su exito
B39: 3) | C39: El investigador se compromete a cumplir con los objetivos y metas definidos en el documento de este plan de acción. De no lograrse los objetivos de manera satisfactoria, se procederá automáticamente a la siguiente etapa en el proceso de planes de mejora (ver detalle al reverso de este documento). Se considerará el plan como concluido exitosamente al alcanzarse el objetivo cada de indicador de desempeño para todas las semanas contempladas. | J39: 3) | K39: El gerente se compromete a dar visibilidad y revisar los resultados obtenidos por el investigador de forma semanal o en el momento que lo solicite el investigador. En caso de no poder brindar los datos por dificultades en la plataforma, esto debera de ser comunicado al investigador.
B40: 4) | C40: El investigador se compromete a no solo concentrarse en la metrica de productividad (IPH) si no tambien en las de Calidad considerandose todas como las metricas establecidas para su puesto | J40: 4) | K40: El gerente le brindara al investigador visibilidad con respecto a las metricas como un todo de manera semanal para ir midiendo el progreso de cada una de ellas.
B41: 5) | C41: El investigador se compromete a evitar cualquier distraccion que pueda afectar su concentracion en este plan. Cumpliendo con nuestras politicas segun el uso correcto de internet y uso de celular en produccion segun el Articulo 3 de Nuestras politicas. | J41: 5) | K41: El Gerente se compromete a realizar un seguimiento detallado semana por semana dando la retroalimentacion necesaria para alcanzar exitosamente el plan.
B42: Evaluacion de defectos de calidad
B43: Acciones por parte del Investigator | J43: Acciones por parte del Gerente
B44: 1) | C44: Se llevaran a acabo sessiones de retroalimentacion semanal con el Gerente o mentor para revisar los defectos recibidos para brindar recomendaciones de mejora en esas areas donde el proceso no es claro | J44: 1) | K44: El gerente asignara el tiempo no productivo necesario para que el investigador pueda revisar completamente los SOP (Guia de trabajo) que esten dudosos y dejar claridad en el procedimiento
B45: 2) | C45: El investigador realizara un analisis de todos los casos enviados por el supervisor para identificar areas de desconocimiento de investigaciones especificas | J45: 2) | K45: Se llevaran sessiones de calibracion con el investigator y equipo cuando sea necesario en reuniones grupales o individuales.
B46: 3) | C46: Se llevaran a acabo revisiones de defectos semanales. Si se dan defectos recurrentes, que sigan impactando nuestros clientes, acciones addicionales se estaran revisando. | J46: 3) | K46: Se llevaran a acabo auditorias despues de revisado el defecto.
...

Sheet PIP ONE- 4 weeks
B2: Plan De Acción
B4: Investigador | C4: Rodrigo Herrera | I4: Inicio | J4: 29 de Marzo de 2026
B6: Gerente directo | C6: Javier Molina | I6: Final | J6: 25 de Abril de 2026
B8: Áreas de mejora
B9: Investigaciones por hora: Cantidad de investigaciones realizadas de manera diaria/ semanal de acuerdo a los requerimientos especificos de la compañia. Cumplimiento de Horario : Uso de tiempo apropiado para efectuar la investigacion de acuerdo a las metricas establecidas para el tipo de investigacion y para el marketplace en que el investigador se encuentra trabajando. NPT: Tiempo no productivo del investigador asignado por su jefe inmediato. Plataformas de trabajo: PARAGON, GeoFence, Paragon reports, manualmente traqueo investigacions resueltas Componetes de Calidad: Defectos seran medidos semanalas
B12: Objetivo y Compromisos
B13: Objectivo: Alcanzar la cantidad semanal y mensual de investigaciones de acuerdo a los objetivos establecidos por la unidad de negocio, este plan de mejora está enfocado a que maximice su productividad y su tiempo efectivamente Compromiso: El investigador se compromete a cumplir con el plan de mejora, sus objetivos y actividades de una buena manera, apertura a la retroalimentación y voluntad para mejorar de acuerdo a la propuesta del gerente
B14: Medidores de Desempeño Plan de Acción Ultimas 4 Semanas | H14: Metas
H15: 1 | I15: 1 | J15: 1 | K15: 1 | L15: L4-L5 revision de resultado
B16: Investigaciones por hora combinado (IPH) | C16: Semana/Week 9 | D16: Semana/Week 10 | E16: Semana/Week 11 | F16: Semana/Week 12 | G16: Semana/Week 13 | H16: Semana/Week 14 | I16: Semana/Week 15 | J16: Semana/Week 16 | K16: Semana/Week 17 | L16: Week 19
C17: =_xlfn.IFNA(VLOOKUP(C16,Sheet2!$A:$B,2,0),"") -> 22 febrero 2026 - 28 febrero 2026 | D17: =_xlfn.IFNA(VLOOKUP(D16,Sheet2!$A:$B,2,0),"") -> 01 marzo 2026 - 07 marzo 2026 | E17: =_xlfn.IFNA(VLOOKUP(E16,Sheet2!$A:$B,2,0),"") -> 08 marzo 2026 - 14 marzo 2026 | F17: =_xlfn.IFNA(VLOOKUP(F16,Sheet2!$A:$B,2,0),"") -> 15 marzo 2026 - 21 marzo 2026 | G17: =_xlfn.IFNA(VLOOKUP(G16,Sheet2!$A:$B,2,0),"") -> 22 marzo 2026 - 28 marzo 2026 | H17: =_xlfn.IFNA(VLOOKUP(H16,Sheet2!$A:$B,2,0),"") -> 29 marzo 2026 - 04 abril 2026 | I17: =_xlfn.IFNA(VLOOKUP(I16,Sheet2!$A:$B,2,0),"") -> 05 abril 2026 - 11 abril 2026 | J17: =_xlfn.IFNA(VLOOKUP(J16,Sheet2!$A:$B,2,0),"") -> 12 abril 2026 - 18 abril 2026 | K17: =_xlfn.IFNA(VLOOKUP(K16,Sheet2!$A:$B,2,0),"") -> 19 abril 2026 - 25 abril 2026
B18: Meta de Investigaciones Combinadas Por Hora (IPH) | C18: 8.6031332 | D18: 8.5416251 | E18: 8.5698688 | F18: 8.491034 | G18: 8.6367328 | H18: 8.5164631 | I18: 9.3394208 | J18: 9.3112392 | K18: 9.4371389 | L18: Notas de resumen
B19: Actual de Investigaciones Combinadas por Hora (IPH) | C19: 10.221275 | D19: 9.2136031 | E19: 9.3930193 | F19: 9.8566859 | G19: 8.5389155 | H19: 8.8100238 | I19: 9.1624019 | J19: 9.0633611 | K19: 9.5989184
B20: Resultado Semanal(Cumple/No Cumple) | C20: Cumple | D20: Cumple | E20: Cumple | F20: Cumple | G20: No cumple | H20: Cumple | I20: No cumple | J20: No cumple | K20: Cumple
B21: Componentes de Calidad RR | C21: =C17 -> 22 febrero 2026 - 28 febrero 2026 | D21: =D17 -> 01 marzo 2026 - 07 marzo 2026 | E21: =E17 -> 08 marzo 2026 - 14 marzo 2026 | F21: =F17 -> 15 marzo 2026 - 21 marzo 2026 | G21: =G17 -> 22 marzo 2026 - 28 marzo 2026 | H21: =H17 -> 29 marzo 2026 - 04 abril 2026 | I21: =I17 -> 05 abril 2026 - 11 abril 2026 | J21: =J17 -> 12 abril 2026 - 18 abril 2026 | K21: =K17 -> 19 abril 2026 - 25 abril 2026 | L21: Week 19
B22: Meta de Porcentage de Investigaciones Reversadas (RR Target) | C22: 0.0058 | D22: 0.0058 | E22: 0.0058 | F22: 0.0058 | G22: 0.0058 | H22: 0.0058 | I22: 0.0058 | J22: 0.0058 | K22: 0.0058 | L22: Notas de resumen
B23: Porcentage de Investigaciones Reversadas Obtenido (RR Actual) | C23: 0 | D23: 0 | E23: 0 | F23: 0 | G23: 0 | H23: 0 | I23: 0 | J23: 0 | K23: 0
B24: Controllable defects | C24: 0 | D24: 0 | E24: 0 | F24: 0 | G24: 0 | H24: 0 | I24: 0 | J24: 0 | K24: 0
B25: Resultado Semanal(Cumple/No Cumple) | C25: Cumple | D25: Cumple | E25: Cumple | F25: Cumple | G25: Cumple | H25: Cumple | I25: Cumple | J25: Cumple | K25: Cumple
B26: Componentes de Calidad MRR | C26: =C17 -> 22 febrero 2026 - 28 febrero 2026 | D26: =D17 -> 01 marzo 2026 - 07 marzo 2026 | E26: =E17 -> 08 marzo 2026 - 14 marzo 2026 | F26: =F17 -> 15 marzo 2026 - 21 marzo 2026 | G26: =G21 -> 22 marzo 2026 - 28 marzo 2026 | H26: =H17 -> 29 marzo 2026 - 04 abril 2026 | I26: =I17 -> 05 abril 2026 - 11 abril 2026 | J26: =J17 -> 12 abril 2026 - 18 abril 2026 | K26: =K17 -> 19 abril 2026 - 25 abril 2026 | L26: Week 19
B27: Meta de Porcentaje de Restauracion no Realizada (MRR Target) | C27: 0.02 | D27: 0.02 | E27: 0.02 | F27: 0.02 | G27: 0.02 | H27: 0.02 | I27: 0.02 | J27: 0.02 | K27: 0.02 | L27: Notas de resumen
B28: Porcentaje de Restauracion No Realizada Obtenido (MRR Actual) | C28: 0 | D28: 0 | E28: 0 | F28: 0 | G28: 0 | H28: 0 | I28: 0 | J28: 0 | K28: 0
B29: Controllable defects | C29: 0 | D29: 0 | E29: 0 | F29: 0 | G29: 0 | H29: 0 | I29: 0 | J29: 0 | K29: 0
B30: Resultado Semanal(Cumple/No Cumple) | C30: Cumple | D30: Cumple | E30: Cumple | F30: Cumple | G30: Cumple | H30: Cumple | I30: Cumple | J30: Cumple | K30: Cumple
B31: Componentes de Calidad CRAR | C31: =C17 -> 22 febrero 2026 - 28 febrero 2026 | D31: =D17 -> 01 marzo 2026 - 07 marzo 2026 | E31: =E17 -> 08 marzo 2026 - 14 marzo 2026 | F31: =F17 -> 15 marzo 2026 - 21 marzo 2026 | G31: =G17 -> 22 marzo 2026 - 28 marzo 2026 | H31: =H17 -> 29 marzo 2026 - 04 abril 2026 | I31: =I17 -> 05 abril 2026 - 11 abril 2026 | J31: =J17 -> 12 abril 2026 - 18 abril 2026 | K31: =K17 -> 19 abril 2026 - 25 abril 2026 | L31: Week 19
B32: Meta de Porcentage de Precision de Respuesta al Cliente (CRAR Target) | C32: 0.95 | D32: 0.95 | E32: 0.95 | F32: 0.95 | G32: 0.95 | H32: 0.95 | I32: 0.95 | J32: 0.95 | K32: 0.95 | L32: Notas de resumen
B33: Porcentage de Precision de Respuesta al Cliente Obtenido (CRAR Actual) | C33: 0.76 | D33: 0.4 | E33: 1 | F33: 0.68 | G33: 0.92 | H33: 1 | I33: 1 | J33: 0.8 | K33: 1
B34: Resultado Semanal(Cumple/No Cumple) | C34: No cumple | D34: No cumple | E34: Cumple | F34: No cumple | G34: No cumple | H34: Cumple | I34: Cumple | J34: No cumple | K34: Cumple
B35: Resultados de Investigaciones por Hora (IPH) *resultados seran revisados semanales
B36: Acciones por parte del Investigator | K36: Acciones por parte del Gerente
B37: 1) | C37: El investigador informara de manera inmediata si tuviese algun problema para efectuar investigaciones , siendo problemas con la plataforma Paragon o con cualquier duda que puedan tener acerca del caso. | J37: 1) | K37: El gerente se compromete a dar visibilidad y revisar los resultados obtenidos de forma semanal.
B38: 2) | C38: El investigador se compromete a dejar claras cuales son las posibles faltas de conocimiento que puedan estar afectando su rapidez y calidad en la toma de decisiones | J38: 2) | K38: El gerente se compromete a darle la prioridad necesaria a este plan y sus actividades con el fin de brindar la ayuda requerida para asegurar su exito
B39: 3) | C39: El investigador se compromete a cumplir con los objetivos y metas definidos en el documento de este plan de acción. De no lograrse los objetivos de manera satisfactoria, se procederá automáticamente a la siguiente etapa en el proceso de planes de mejora (ver detalle al reverso de este documento). Se considerará el plan como concluido exitosamente al alcanzarse el objetivo cada de indicador de desempeño para todas las semanas contempladas. | J39: 3) | K39: El gerente se compromete a dar visibilidad y revisar los resultados obtenidos por el investigador de forma semanal o en el momento que lo solicite el investigador. En caso de no poder brindar los datos por dificultades en la plataforma, esto debera de ser comunicado al investigador.
B40: 4) | C40: El investigador se compromete a no solo concentrarse en la metrica de productividad (IPH) si no tambien en las de Calidad considerandose todas como las metricas establecidas para su puesto | J40: 4) | K40: El gerente le brindara al investigador visibilidad con respecto a las metricas como un todo de manera semanal para ir midiendo el progreso de cada una de ellas.
B41: 5) | C41: El investigador se compromete a evitar cualquier distraccion que pueda afectar su concentracion en este plan. Cumpliendo con nuestras politicas segun el uso correcto de internet y uso de celular en produccion segun el Articulo 3 de Nuestras politicas. | J41: 5) | K41: El Gerente se compromete a realizar un seguimiento detallado semana por semana dando la retroalimentacion necesaria para alcanzar exitosamente el plan.
B42: Evaluacion de defectos de calidad
B43: Acciones por parte del Investigator | J43: Acciones por parte del Gerente
B44: 1) | C44: Se llevaran a acabo sessiones de retroalimentacion semanal con el Gerente o mentor para revisar los defectos recibidos para brindar recomendaciones de mejora en esas areas donde el proceso no es claro | J44: 1) | K44: El gerente asignara el tiempo no productivo necesario para que el investigador pueda revisar completamente los SOP (Guia de trabajo) que esten dudosos y dejar claridad en el procedimiento
B45: 2) | C45: El investigador realizara un analisis de todos los casos enviados por el supervisor para identificar areas de desconocimiento de investigaciones especificas | J45: 2) | K45: Se llevaran sessiones de calibracion con el investigator y equipo cuando sea necesario en reuniones grupales o individuales.
B46: 3) | C46: Se llevaran a acabo revisiones de defectos semanales. Si se dan defectos recurrentes, que sigan impactando nuestros clientes, acciones addicionales se estaran revisando. | J46: 3) | K46: Se llevaran a acabo auditorias despues de revisado el defecto.
...

Sheet PIP TWO- 4 weeks 
B2: Plan De Acción
B4: Investigador | C4: Rodrigo Herrera | I4: Inicio | J4: 10 de mayo de 2026
B6: Gerente directo | C6: Javier Molina | I6: Final | J6: 6 de junio de 2026
B8: Áreas de mejora
B9: Investigaciones por hora: Cantidad de investigaciones realizadas de manera diaria/ semanal de acuerdo a los requerimientos especificos de la compañia. Cumplimiento de Horario : Uso de tiempo apropiado para efectuar la investigacion de acuerdo a las metricas establecidas para el tipo de investigacion y para el marketplace en que el investigador se encuentra trabajando. NPT: Tiempo no productivo del investigador asignado por su jefe inmediato. Plataformas de trabajo: PARAGON, GeoFence, Paragon reports, manualmente traqueo investigacions resueltas Componetes de Calidad: Defectos seran medidos semanalas
B12: Objetivo y Compromisos
B13: Objectivo: Alcanzar la cantidad semanal y mensual de investigaciones de acuerdo a los objetivos establecidos por la unidad de negocio, este plan de mejora está enfocado a que maximice su productividad y su tiempo efectivamente Compromiso: El investigador se compromete a cumplir con el plan de mejora, sus objetivos y actividades de una buena manera, apertura a la retroalimentación y voluntad para mejorar de acuerdo a la propuesta del gerente
B14: Medidores de Desempeño Plan de Acción Ultimas 4 Semanas | H14: Metas
H15: 1 | I15: 1 | J15: 1 | K15: 1 | L15: L4-L5 revision de resultado
B16: Investigaciones por hora combinado (IPH) | C16: Semana/Week 15 | D16: Semana/Week 16 | E16: Semana/Week 17 | F16: Semana/Week 18 | G16: Semana/Week 19 | H16: Semana/Week 20 | I16: Semana/Week 21 | J16: Semana/Week 22 | K16: Semana/Week 23 | L16: Week 26/27
C17: =_xlfn.IFNA(VLOOKUP(C16,Sheet2!$A:$B,2,0),"") -> 05 abril 2026 - 11 abril 2026 | D17: =_xlfn.IFNA(VLOOKUP(D16,Sheet2!$A:$B,2,0),"") -> 12 abril 2026 - 18 abril 2026 | E17: =_xlfn.IFNA(VLOOKUP(E16,Sheet2!$A:$B,2,0),"") -> 19 abril 2026 - 25 abril 2026 | F17: =_xlfn.IFNA(VLOOKUP(F16,Sheet2!$A:$B,2,0),"") -> 26 abril 2026 - 02 mayo 2026 | G17: =_xlfn.IFNA(VLOOKUP(G16,Sheet2!$A:$B,2,0),"") -> 03 mayo 2026 - 09 mayo 2026 | H17: =_xlfn.IFNA(VLOOKUP(H16,Sheet2!$A:$B,2,0),"") -> 10 mayo 2026 - 16 mayo 2026 | I17: =_xlfn.IFNA(VLOOKUP(I16,Sheet2!$A:$B,2,0),"") -> 17 mayo 2026 - 23 mayo 2026 | J17: =_xlfn.IFNA(VLOOKUP(J16,Sheet2!$A:$B,2,0),"") -> 24 mayo 2026 - 30 mayo 2026 | K17: =_xlfn.IFNA(VLOOKUP(K16,Sheet2!$A:$B,2,0),"") -> 31 mayo 2026 - 06 junio 2026
B18: Meta de Investigaciones Combinadas Por Hora (IPH) | C18: 9.3394208 | D18: 9.3112392 | E18: 9.4371389 | F18: 9.3856883 | G18: 9.2908226 | H18: 9.4847844 | L18: Notas de resumen
B19: Actual de Investigaciones Combinadas por Hora (IPH) | C19: 9.1624019 | D19: 9.0633611 | E19: 9.5989184 | F19: 9.1442415 | G19: 9.6305252 | H19: 9.5817695
B20: Resultado Semanal(Cumple/No Cumple) | C20: No cumple | D20: No cumple | E20: Cumple | F20: No cumple | G20: Cumple | H20: Cumple
B21: Componentes de Calidad RR | C21: =C17 -> 05 abril 2026 - 11 abril 2026 | D21: =D17 -> 12 abril 2026 - 18 abril 2026 | E21: =E17 -> 19 abril 2026 - 25 abril 2026 | F21: =F17 -> 26 abril 2026 - 02 mayo 2026 | G21: =G17 -> 03 mayo 2026 - 09 mayo 2026 | H21: =H17 -> 10 mayo 2026 - 16 mayo 2026 | I21: =I17 -> 17 mayo 2026 - 23 mayo 2026 | J21: =J17 -> 24 mayo 2026 - 30 mayo 2026 | K21: =K17 -> 31 mayo 2026 - 06 junio 2026 | L21: Week 26/27
B22: Meta de Porcentage de Investigaciones Reversadas (RR Target) | C22: 0.0058 | D22: 0.0058 | E22: 0.0058 | F22: 0.0058 | L22: Notas de resumen
B23: Porcentage de Investigaciones Reversadas Obtenido (RR Actual) | C23: 0 | D23: 0 | E23: 0 | F23: 0
B24: Controllable defects | C24: 0 | D24: 0 | E24: 0 | F24: 0
B25: Resultado Semanal(Cumple/No Cumple) | C25: Cumple | D25: Cumple | E25: Cumple | F25: Cumple
B26: Componentes de Calidad MRR | C26: =C17 -> 05 abril 2026 - 11 abril 2026 | D26: =D17 -> 12 abril 2026 - 18 abril 2026 | E26: =E17 -> 19 abril 2026 - 25 abril 2026 | F26: =F17 -> 26 abril 2026 - 02 mayo 2026 | G26: =G21 -> 03 mayo 2026 - 09 mayo 2026 | H26: =H17 -> 10 mayo 2026 - 16 mayo 2026 | I26: =I17 -> 17 mayo 2026 - 23 mayo 2026 | J26: =J17 -> 24 mayo 2026 - 30 mayo 2026 | K26: =K17 -> 31 mayo 2026 - 06 junio 2026 | L26: Week 26/27
B27: Meta de Porcentaje de Restauracion no Realizada (MRR Target) | C27: 0.02 | D27: 0.02 | E27: 0.02 | F27: 0.02 | G27: 0.02 | H27: 0.02 | L27: Notas de resumen
B28: Porcentaje de Restauracion No Realizada Obtenido (MRR Actual) | C28: 0.02 | D28: 0 | E28: 0 | F28: 0 | G28: 0.02 | H28: 0
B29: Controllable defects | C29: 1 | D29: 0 | E29: 0 | F29: 0 | G29: 1 | H29: 0
B30: Resultado Semanal(Cumple/No Cumple) | C30: No cumple | D30: Cumple | E30: Cumple | F30: Cumple | G30: No cumple | H30: No info yet
B31: Componentes de Calidad CRAR | C31: =C17 -> 05 abril 2026 - 11 abril 2026 | D31: =D17 -> 12 abril 2026 - 18 abril 2026 | E31: =E17 -> 19 abril 2026 - 25 abril 2026 | F31: =F17 -> 26 abril 2026 - 02 mayo 2026 | G31: =G17 -> 03 mayo 2026 - 09 mayo 2026 | H31: =H17 -> 10 mayo 2026 - 16 mayo 2026 | I31: =I17 -> 17 mayo 2026 - 23 mayo 2026 | J31: =J17 -> 24 mayo 2026 - 30 mayo 2026 | K31: =K17 -> 31 mayo 2026 - 06 junio 2026 | L31: Week 26/27
B32: Meta de Porcentage de Precision de Respuesta al Cliente (CRAR Target) | C32: 0.95 | D32: 0.95 | E32: 0.95 | F32: 0.95 | G32: 0.95 | H32: 0.95 | I32: 0.95 | J32: 0.95 | K32: 0.95 | L32: Notas de resumen
B33: Porcentage de Precision de Respuesta al Cliente Obtenido (CRAR Actual) | C33: 1 | D33: 0.8 | E33: 1 | F33: 0.8 | G33: 1 | H33: 0.6
B34: Resultado Semanal(Cumple/No Cumple) | C34: Cumple | D34: No cumple | E34: Cumple | F34: No cumple | G34: Cumple | H34: No cumple
B35: Resultados de Investigaciones por Hora (IPH) *resultados seran revisados semanales
B36: Acciones por parte del Investigator | K36: Acciones por parte del Gerente
B37: 1) | C37: El investigador informara de manera inmediata si tuviese algun problema para efectuar investigaciones , siendo problemas con la plataforma Paragon o con cualquier duda que puedan tener acerca del caso. | J37: 1) | K37: El gerente se compromete a dar visibilidad y revisar los resultados obtenidos de forma semanal.
B38: 2) | C38: El investigador se compromete a dejar claras cuales son las posibles faltas de conocimiento que puedan estar afectando su rapidez y calidad en la toma de decisiones | J38: 2) | K38: El gerente se compromete a darle la prioridad necesaria a este plan y sus actividades con el fin de brindar la ayuda requerida para asegurar su exito
B39: 3) | C39: El investigador se compromete a cumplir con los objetivos y metas definidos en el documento de este plan de acción. De no lograrse los objetivos de manera satisfactoria, se procederá automáticamente a la siguiente etapa en el proceso de planes de mejora (ver detalle al reverso de este documento). Se considerará el plan como concluido exitosamente al alcanzarse el objetivo cada de indicador de desempeño para todas las semanas contempladas. | J39: 3) | K39: El gerente se compromete a dar visibilidad y revisar los resultados obtenidos por el investigador de forma semanal o en el momento que lo solicite el investigador. En caso de no poder brindar los datos por dificultades en la plataforma, esto debera de ser comunicado al investigador.
B40: 4) | C40: El investigador se compromete a no solo concentrarse en la metrica de productividad (IPH) si no tambien en las de Calidad considerandose todas como las metricas establecidas para su puesto | J40: 4) | K40: El gerente le brindara al investigador visibilidad con respecto a las metricas como un todo de manera semanal para ir midiendo el progreso de cada una de ellas.
B41: 5) | C41: El investigador se compromete a evitar cualquier distraccion que pueda afectar su concentracion en este plan. Cumpliendo con nuestras politicas segun el uso correcto de internet y uso de celular en produccion segun el Articulo 3 de Nuestras politicas. | J41: 5) | K41: El Gerente se compromete a realizar un seguimiento detallado semana por semana dando la retroalimentacion necesaria para alcanzar exitosamente el plan.
B42: Evaluacion de defectos de calidad
B43: Acciones por parte del Investigator | J43: Acciones por parte del Gerente
B44: 1) | C44: Se llevaran a acabo sessiones de retroalimentacion semanal con el Gerente o mentor para revisar los defectos recibidos para brindar recomendaciones de mejora en esas areas donde el proceso no es claro | J44: 1) | K44: El gerente asignara el tiempo no productivo necesario para que el investigador pueda revisar completamente los SOP (Guia de trabajo) que esten dudosos y dejar claridad en el procedimiento
B45: 2) | C45: El investigador realizara un analisis de todos los casos enviados por el supervisor para identificar areas de desconocimiento de investigaciones especificas | J45: 2) | K45: Se llevaran sessiones de calibracion con el investigator y equipo cuando sea necesario en reuniones grupales o individuales.
B46: 3) | C46: Se llevaran a acabo revisiones de defectos semanales. Si se dan defectos recurrentes, que sigan impactando nuestros clientes, acciones addicionales se estaran revisando. | J46: 3) | K46: Se llevaran a acabo auditorias despues de revisado el defecto.
...

Sheet Sheet2
A1: Semana/Week 1 | B1: 28 diciembre 2025 - 03 enero 2026
A2: Semana/Week 2 | B2: 04 enero 2026 - 10 enero 2026
A3: Semana/Week 3 | B3: 11 enero 2026 - 17 enero 2026
A4: Semana/Week 4 | B4: 18 enero 2026 - 24 enero 2026
A5: Semana/Week 5 | B5: 25 enero 2026 - 31 enero 2026
A6: Semana/Week 6 | B6: 01 febrero 2026 - 07 febrero 2026
A7: Semana/Week 7 | B7: 08 febrero 2026 - 14 febrero 2026
A8: Semana/Week 8 | B8: 15 febrero 2026 - 21 febrero 2026
A9: Semana/Week 9 | B9: 22 febrero 2026 - 28 febrero 2026
A10: Semana/Week 10 | B10: 01 marzo 2026 - 07 marzo 2026
A11: Semana/Week 11 | B11: 08 marzo 2026 - 14 marzo 2026
A12: Semana/Week 12 | B12: 15 marzo 2026 - 21 marzo 2026
... A53: Semana/Week 53 | B53: 27 diciembre 2026 - 02 enero 2027
